<?xml version="1.0" ?>
<!-- =================================================================================== -->
<!-- |    This document was autogenerated by xacro from robotino_simple.urdf.xacro     | -->
<!-- |    EDITING THIS FILE BY HAND IS NOT RECOMMENDED                                 | -->
<!-- =================================================================================== -->
<robot name="robot" xmlns:xacro="http://www.ros.org/wiki/xacro">
  <!-- ****************** -->
  <!-- ***** COMMON ***** -->
  <!-- ****************** -->
  <!-- camera mount positions | handeye calibration | relative to base_link -->
  <!-- hokuyo mount positions | relative to base_link -->
  <!-- tilt mount positions | handeye calibration | relative to base_link -->
  <!-- arm mount positions | handeye calibration | relative to base_link -->
  <!-- arm calibration-->
  <!-- kinect mount positions | handeye calibration | relative to tilt_link -->
  <!-- anglebracketusb mount positions | handeye calibration | relative to base_link -->
  <!--gazebo>
    <plugin name="gazebo_ros_control" filename="libgazebo_ros_control.so">
      <robotNamespace>/robotino</robotNamespace>
    </plugin>
  </gazebo-->
  <!-- WHEEL -->
  <!-- Wheel transmission   -->
  <!-- COMMAND BRIDGE -->
  <!--GAZEBO PLUGIN-->
  <!-- GAZEBO OPENNI PLUGIN -->
  <!-- accesories -->
  <!-- SOFT HAND MODEL -->
  <!--<link name="${name}_footprint"/>
   
   <joint name="${name}_footprint_joint" type="fixed">
      <origin xyz="0 0 0" rpy="0 0 0" />
      <child link="${name}_link" />
      <parent link="${name}_footprint"/>
   </joint> -->
  <link name="base_link">
    <inertial>
      <mass value="20"/>
      <origin xyz="0 0 0"/>
      <inertia ixx="75.0" ixy="0.0" ixz="0.0" iyy="75.0" iyz="0.0" izz="75.0"/>
    </inertial>
    <visual>
      <origin rpy="0 0 0" xyz="0 0 0"/>
      <geometry>
        <mesh filename="package://robotino_description/meshes/RobotinoBody.dae"/>
        <!--cylinder length="0.24" radius="0.23"/-->
      </geometry>
    </visual>
    <collision>
      <origin rpy="0 0 0" xyz="0 0 0"/>
      <geometry>
        <mesh filename="package://robotino_description/meshes/RobotinoBody.dae"/>
        <!--cylinder length="0.24" radius="0.23"/-->
      </geometry>
    </collision>
  </link>
  <gazebo reference="base_link">
    <material>Gazebo/Grey</material>
    <gravity>true</gravity>
    <self_collide>false</self_collide>
    <sensor name="base_contact_sensor" type="contact">
      <always_on>true</always_on>
      <update_rate>100.0</update_rate>
      <contact>
        <collision>base_link_collision</collision>
        <topic>base_bumper</topic>
      </contact>
      <plugin filename="libgazebo_ros_bumper.so" name="base_gazebo_ros_bumper_controller">
        <frameName>world</frameName>
        <bumperTopicName>base_bumper</bumperTopicName>
      </plugin>
    </sensor>
  </gazebo>
  <!--gazebo>
      <plugin name="p3d_base_controller" filename="libgazebo_ros_p3d.so">
        <alwaysOn>true</alwaysOn>
        <updateRate>100.0</updateRate>
        <bodyName>${name}_link</bodyName>
        <topicName>${name}_pose_ground_truth</topicName>
        <frameName>map</frameName>
        <xyzOffsets>25.7 25.7 0</xyzOffsets-->
  <!-- initialize odometry for fake localization-->
  <!--rpyOffsets>0 0 0</rpyOffsets>
        <gaussianNoise>0.01</gaussianNoise>
      </plugin>
      <canonicalBody>${name}_footprint</canonicalBody>
    </gazebo-->
  <!-- position controller -->
  <gazebo>
    <plugin filename="libgazebo_ros_planar_move.so" name="base_controller">
      <commandTopic>cmd_vel</commandTopic>
      <odometryTopic>odom</odometryTopic>
      <odometryFrame>odom</odometryFrame>
      <odometryRate>20.0</odometryRate>
      <robotBaseFrame>base_link</robotBaseFrame>
    </plugin>
  </gazebo>
  <!--wheel name="wheel0" parent="base_link">
      <origin xyz="0.095 0.14 0.02" rpy="0 0 ${M_PI/3}"/>
      <axis xyz="-1 0 0"/>
    </wheel>
    <wheel_transmission name="wheel0" />
    <wheel_gazebo name="wheel0" />
    <wheel name="wheel1" parent="base_link">
      <origin xyz="-0.16 0 0.02" rpy="0 0 0"/>
      <axis xyz="1 0 0"/>
    </wheel>
    <wheel_transmission name="wheel1" />
    <wheel_gazebo name="wheel1" />
    <wheel name="wheel2" parent="base_link">
      <origin xyz="0.105 -0.15 0.02" rpy="0 0 -${M_PI/3}"/>
      <axis xyz="-1 0 0"/>
    </wheel>
    <wheel_transmission name="wheel2" />
    <wheel_gazebo name="wheel2" />


    <command_bridge name="command_bridge" parent="base_link">
      <origin xyz="-0.05 0 0.13" rpy="0 0 ${M_PI/2}"/>
    </command_bridge-->
  <!--hokuyo name="hokuyo" parent="base_link">
    <origin xyz="${hokuyo_x} ${hokuyo_y} ${hokuyo_z}" rpy="${hokuyo_roll} ${hokuyo_pitch} ${hokuyo_yaw}"/>
  </hokuyo-->
  <joint name="fixed_base_link_base" type="fixed">
    <parent link="base_link"/>
    <child link="base"/>
    <origin rpy="0 0 -1.0471975511965976" xyz="0.0 0.0 0.185"/>
  </joint>
  <link name="odomp"/>
  <joint name="rotatory" type="continuous">
    <parent link="odomp"/>
    <child link="base_link"/>
    <axis xyz="0 0 1"/>
  </joint>
  <link name="base">
    <inertial>
      <mass value="0.01"/>
      <origin xyz="0 0 0"/>
      <inertia ixx="0.001" ixy="0.0" ixz="0.0" iyy="0.001" iyz="0.0" izz="0.001"/>
    </inertial>
    <visual>
      <geometry>
        <cylinder length="0.105" radius="0.005"/>
      </geometry>
      <material name="blue">
        <color rgba="0 0 .8 1"/>
      </material>
      <origin rpy="0 0.01 0.01" xyz="0 0 0.0525"/>
    </visual>
  </link>
  <joint name="fixed_base_motor1" type="fixed">
    <parent link="base"/>
    <child link="motor1"/>
    <origin rpy="0 0 0" xyz="0.0 -0.01591 0.140"/>
  </joint>
  <link name="motor1">
    <inertial>
      <mass value="0.01"/>
      <origin xyz="0 0 0"/>
      <inertia ixx="0.001" ixy="0.0" ixz="0.0" iyy="0.001" iyz="0.0" izz="0.001"/>
    </inertial>
    <visual>
      <geometry>
        <box size="0.07 0.123 0.067"/>
      </geometry>
      <material name="blue">
        <color rgba="0 0 .8 1"/>
      </material>
      <origin rpy="0 0 0" xyz="0 0.0615 0."/>
    </visual>
  </link>
  <joint name="joint1" type="revolute">
    <parent link="motor1"/>
    <child link="link1"/>
    <origin rpy="0 0 0" xyz="0.0 0.0 0."/>
    <axis xyz="0 1 0"/>
    <limit effort="400" lower="-1.8325957145940461" upper="1.8325957145940461" velocity="30"/>
  </joint>
  <link name="link1">
    <inertial>
      <mass value="0.01"/>
      <origin xyz="0 0 0"/>
      <inertia ixx="0.001" ixy="0.0" ixz="0.0" iyy="0.001" iyz="0.0" izz="0.001"/>
    </inertial>
    <visual>
      <geometry>
        <box size="0.06 0.012 0.3"/>
      </geometry>
      <material name="blue"/>
      <origin rpy="0 0 0" xyz="0 0. 0.125"/>
    </visual>
  </link>
  <gazebo reference="link1">
    <material>Gazebo/Black</material>
  </gazebo>
  <joint name="joint2" type="revolute">
    <parent link="link1"/>
    <child link="motor2"/>
    <origin rpy="0 0 0" xyz="0.0 0.0 0.250"/>
    <axis xyz="0 1 0"/>
    <limit effort="190" lower="-2.443460952792061" upper="2.443460952792061" velocity="30"/>
  </joint>
  <link name="motor2">
    <inertial>
      <mass value="0.01"/>
      <origin xyz="0 0 0"/>
      <inertia ixx="0.001" ixy="0.0" ixz="0.0" iyy="0.001" iyz="0.0" izz="0.001"/>
    </inertial>
    <visual>
      <geometry>
        <box size="0.064 0.125 0.054"/>
      </geometry>
      <material name="blue"/>
      <origin rpy="0 0 0" xyz="0 0.0625 0."/>
    </visual>
  </link>
  <joint name="fixed_motor2_link2" type="fixed">
    <parent link="motor2"/>
    <child link="link2"/>
    <origin rpy="0 0 0" xyz="0.0 0.098 0.027"/>
  </joint>
  <link name="link2">
    <inertial>
      <mass value="0.01"/>
      <origin xyz="0 0 0"/>
      <inertia ixx="0.001" ixy="0.0" ixz="0.0" iyy="0.001" iyz="0.0" izz="0.001"/>
    </inertial>
    <visual>
      <geometry>
        <box size="0.064 0.054 0.158"/>
      </geometry>
      <material name="blue"/>
      <origin rpy="0 0 0" xyz="0.0 0.0 0.079"/>
    </visual>
  </link>
  <gazebo reference="link2">
    <material>Gazebo/Grey</material>
  </gazebo>
  <joint name="joint3" type="revolute">
    <parent link="link2"/>
    <child link="link3"/>
    <origin rpy="0 0 0" xyz="0.0 0.0 0.158"/>
    <axis xyz="0 0 1"/>
    <limit effort="190" lower="-3.141592653589793" upper="3.141592653589793" velocity="30"/>
  </joint>
  <link name="link3">
    <inertial>
      <mass value="0.01"/>
      <origin xyz="0 0 0"/>
      <inertia ixx="0.001" ixy="0.0" ixz="0.0" iyy="0.001" iyz="0.0" izz="0.001"/>
    </inertial>
    <visual>
      <geometry>
        <box size="0.052 0.084 0.086"/>
      </geometry>
      <material name="blue"/>
      <origin rpy="0 0 0" xyz="0 -0.015 0.043"/>
    </visual>
  </link>
  <gazebo reference="link3">
    <material>Gazebo/Black</material>
  </gazebo>
  <joint name="joint4" type="revolute">
    <parent link="link3"/>
    <child link="link4"/>
    <origin rpy="0 0 0" xyz="0.0 -0.057 0.065"/>
    <axis xyz="0 1 0"/>
    <limit effort="160" lower="-3.141592653589793" upper="3.141592653589793" velocity="30"/>
  </joint>
  <link name="link4">
    <inertial>
      <mass value="0.01"/>
      <origin xyz="0 0 0"/>
      <inertia ixx="0.001" ixy="0.0" ixz="0.0" iyy="0.001" iyz="0.0" izz="0.001"/>
    </inertial>
    <visual>
      <geometry>
        <box size="0.042 0.042 0.084"/>
      </geometry>
      <material name="blue"/>
      <origin rpy="0 0 0" xyz="0. -0.021 -0.007"/>
    </visual>
  </link>
  <gazebo reference="link4">
    <material>Gazebo/Grey</material>
  </gazebo>
  <joint name="joint5" type="revolute">
    <parent link="link4"/>
    <child link="link5"/>
    <origin rpy="0 0 0" xyz="0.0 -0.027 0.035"/>
    <axis xyz="0 0 1"/>
    <limit effort="160" lower="-3.141592653589793" upper="3.141592653589793" velocity="30"/>
  </joint>
  <link name="link5">
    <inertial>
      <mass value="0.01"/>
      <origin xyz="0 0 0"/>
      <inertia ixx="0.001" ixy="0.0" ixz="0.0" iyy="0.001" iyz="0.0" izz="0.001"/>
    </inertial>
  </link>
  <gazebo reference="link5">
    <material>Gazebo/Black</material>
  </gazebo>
  <transmission name="arm_1_trans">
    <type>transmission_interface/SimpleTransmission</type>
    <joint name="joint1">
      <hardwareInterface>PositionJointInterface</hardwareInterface>
      <hardwareInterface>VelocityJointInterface</hardwareInterface>
    </joint>
    <actuator name="arm_1_motor">
      <mechanicalReduction>1</mechanicalReduction>
    </actuator>
  </transmission>
  <transmission name="arm_2_trans">
    <type>transmission_interface/SimpleTransmission</type>
    <joint name="joint2">
      <hardwareInterface>PositionJointInterface</hardwareInterface>
      <hardwareInterface>VelocityJointInterface</hardwareInterface>
    </joint>
    <actuator name="arm_2_motor">
      <mechanicalReduction>1</mechanicalReduction>
    </actuator>
  </transmission>
  <transmission name="arm_3_trans">
    <type>transmission_interface/SimpleTransmission</type>
    <joint name="joint3">
      <hardwareInterface>PositionJointInterface</hardwareInterface>
      <hardwareInterface>VelocityJointInterface</hardwareInterface>
    </joint>
    <actuator name="arm_3_motor">
      <mechanicalReduction>1</mechanicalReduction>
    </actuator>
  </transmission>
  <transmission name="arm_4_trans">
    <type>transmission_interface/SimpleTransmission</type>
    <joint name="joint4">
      <hardwareInterface>PositionJointInterface</hardwareInterface>
      <hardwareInterface>VelocityJointInterface</hardwareInterface>
    </joint>
    <actuator name="arm_4_motor">
      <mechanicalReduction>1</mechanicalReduction>
    </actuator>
  </transmission>
  <transmission name="arm_5_trans">
    <type>transmission_interface/SimpleTransmission</type>
    <joint name="joint5">
      <hardwareInterface>PositionJointInterface</hardwareInterface>
      <hardwareInterface>VelocityJointInterface</hardwareInterface>
    </joint>
    <actuator name="arm_5_motor">
      <mechanicalReduction>1</mechanicalReduction>
    </actuator>
  </transmission>
  <transmission name="arm_6_trans">
    <type>transmission_interface/SimpleTransmission</type>
    <joint name="joint6">
      <hardwareInterface>PositionJointInterface</hardwareInterface>
      <hardwareInterface>VelocityJointInterface</hardwareInterface>
    </joint>
    <actuator name="arm_6_motor">
      <mechanicalReduction>1</mechanicalReduction>
    </actuator>
  </transmission>
  <transmission name="arm_7_trans">
    <type>transmission_interface/SimpleTransmission</type>
    <joint name="joint7">
      <hardwareInterface>PositionJointInterface</hardwareInterface>
      <hardwareInterface>VelocityJointInterface</hardwareInterface>
    </joint>
    <actuator name="arm_7_motor">
      <mechanicalReduction>1</mechanicalReduction>
    </actuator>
  </transmission>
  <gazebo>
    <plugin filename="libhwi_switch_gazebo_ros_control.so" name="ros_control">
      <robotNamespace>arm_controller</robotNamespace>
      <filterJointsParam>joint_names</filterJointsParam>
    </plugin>
  </gazebo>
  <!-- PACMAN VERION ALREADY INCLUDES THE COUPLER, CLAMP AND BASE -->
  <!-- Wrist_sensor -->
  <joint name="wrist_joint" type="fixed">
    <origin rpy="0 0 0" xyz="0.0 0.0 0.0"/>
    <parent link="link5"/>
    <child link="wrist_link"/>
  </joint>
  <link name="wrist_link">
    <gravity>0</gravity>
    <inertial>
      <origin rpy="0 0 0" xyz="0.01557 -0.035456 0.0089893"/>
      <mass value="0.090062"/>
      <inertia ixx="0.00019055" ixy="-9.6717E-07" ixz="-9.3483E-06" iyy="6.2823E-05" iyz="-5.5839E-07" izz="0.00017976"/>
    </inertial>
    <visual>
      <origin rpy="0 0 0" xyz="0 0 0"/>
      <geometry>
        <mesh filename="package://robotino_description/meshes/wrist.stl"/>
      </geometry>
      <material name="">
        <color rgba="0.79216 0.81961 0.93333 1"/>
      </material>
    </visual>
    <collision>
      <origin rpy="0 0 0" xyz="0 0 0"/>
      <geometry>
        <mesh filename="package://robotino_description/meshes/wrist.stl"/>
      </geometry>
    </collision>
  </link>
  <joint name="coupler_joint" type="fixed">
    <origin rpy="0 0 0" xyz="0 0 0.05"/>
    <parent link="wrist_link"/>
    <child link="coupler_link"/>
  </joint>
  <link name="coupler_link">
    <gravity>0</gravity>
    <inertial>
      <origin rpy="0 0 0" xyz="0.01557 -0.035456 0.0089893"/>
      <mass value="0.090062"/>
      <inertia ixx="0.00019055" ixy="-9.6717E-07" ixz="-9.3483E-06" iyy="6.2823E-05" iyz="-5.5839E-07" izz="0.00017976"/>
    </inertial>
    <visual>
      <origin rpy="0 0 0" xyz="0 0 0"/>
      <geometry>
        <mesh filename="package://robotino_description/meshes/coupler.stl"/>
      </geometry>
      <material name="">
        <color rgba="0.79216 0.81961 0.93333 1"/>
      </material>
    </visual>
    <collision>
      <origin rpy="0 0 0" xyz="0 0 0"/>
      <geometry>
        <mesh filename="package://robotino_description/meshes/coupler.stl"/>
      </geometry>
    </collision>
  </link>
  <!-- CLAMP -->
  <xacro:clamp name="soft_hand_clamp" parent="coupler_link">
    <origin rpy="0 0 0" xyz="0 0 0.02"/>
  </xacro:clamp>
  <!-- PALM -->
  <joint name="soft_hand_palm_joint" type="fixed">
    <origin rpy="0 0 0" xyz="0.002 -0.00695 0.09"/>
    <parent link="coupler_link"/>
    <child link="soft_hand_palm_link"/>
  </joint>
  <link name="soft_hand_palm_link">
    <inertial>
      <origin rpy="0 0 0" xyz="0.01557 -0.035456 0.0089893"/>
      <mass value="0.090062"/>
      <inertia ixx="0.00019055" ixy="-9.6717E-07" ixz="-9.3483E-06" iyy="6.2823E-05" iyz="-5.5839E-07" izz="0.00017976"/>
    </inertial>
    <visual>
      <geometry>
        <box size="0.1 0.02 0.15"/>
      </geometry>
    </visual>
    <collision>
      <geometry>
        <box size="0.1 0.02 0.15"/>
      </geometry>
    </collision>
  </link>
  <!--gazebo>
    <plugin name="ros_control" filename="libhwi_switch_gazebo_ros_control.so">
      <robotNamespace>hand_controller</robotNamespace>
      <filterJointsParam>joint_names</filterJointsParam>
    </plugin>
  </gazebo-->
</robot>

