<robot name="robotino">

	<link name="linkbase">
	
		<collision>
		
			<geometry>
				<box size="0.04096 0.0473 0.105" />
			</geometry>
			<origin rpy="0 0 0" xyz="0 0 0.0525"/>
			
		</collision>
		
		<visual>
			<geometry>
				<box size="0.04096 0.0473 0.105" />
			</geometry>
			<material name="white">
				<color rgba="1 1 1 1"/>
			</material>
			<origin rpy="0 0 0" xyz="0 0 0.0525"/>
		</visual>
	
	</link>
	
	<link name="linkbasemotor">
	
		<collision>
			<origin rpy="0 0 0" xyz="0 0 0"/>
			<geometry>
			  <mesh filename="package://uibk_arm_model/meshes/motor1_collision.stl"/>
			</geometry>
		</collision>
		
		<visual>
			<geometry>
				<mesh filename="package://uibk_arm_model/meshes/motor1.stl"/>
			</geometry>
			<material name="white" />
			<origin rpy="0 0 0" xyz="0 0 0"/>
		</visual>
	
	</link>
	
	<link name="link1">
	
		<collision>
			<origin rpy="0 0 0" xyz="0 0 0"/>
			<geometry>
			  <mesh filename="package://uibk_arm_model/meshes/link1_collision.stl"/>
			</geometry>
		</collision>
		
		<visual>
			<geometry>
				<mesh filename="package://uibk_arm_model/meshes/link1.stl"/>
			</geometry>
			<material name="white" />
			<origin rpy="0 0 0" xyz="0 0 0"/>
		</visual>
	
	</link>
	
	<link name="link2">
	
		<collision>
			<origin rpy="0 0 0" xyz="0 0 0"/>
			<geometry>
			  <mesh filename="package://uibk_arm_model/meshes/link2_collision.stl"/>
			</geometry>
		</collision>
		
		<visual>
			<geometry>
				<mesh filename="package://uibk_arm_model/meshes/link2.stl"/>
			</geometry>
			<material name="white" />
			<origin rpy="0 0 0" xyz="0 0 0"/>
		</visual>
	
	</link>
	
	<link name="link3">
	
		<collision>
			<origin rpy="0 0 0" xyz="0 0 0"/>
			<geometry>
			  <mesh filename="package://uibk_arm_model/meshes/link3_collision.stl"/>
			</geometry>
		</collision>
		
		<visual>
			<geometry>
				<mesh filename="package://uibk_arm_model/meshes/link3.stl"/>
			</geometry>
			<material name="white" />
			<origin rpy="0 0 0" xyz="0 0 0"/>
		</visual>
	
	</link>
	
	<link name="link4">
	
		<collision>
			<origin rpy="0 0 0" xyz="0 0 0"/>
			<geometry>
			  <mesh filename="package://uibk_arm_model/meshes/link4_collision.stl"/>
			</geometry>
		</collision>
		
		<visual>
			<geometry>
				<mesh filename="package://uibk_arm_model/meshes/link4.stl"/>
			</geometry>
			<material name="white" />
			<origin rpy="0 0 0" xyz="0 0 0"/>
		</visual>
		
	</link>
	
	<link name="link5">
		
	</link>
	
	<link name="linkhandbase">
		
	</link>

	<joint name="baserot" type="revolute">
		<parent link="linkbase"/>
		<child link="linkbasemotor"/>
		<axis xyz="0 0 1" />
		<origin xyz="0.0 -0.01591 0.140" rpy="0 0 0" />
		<limit upper="1.7" lower="-1.7" effort="160" velocity="30" />
	</joint>

	<joint name="armjoint1" type="revolute">
		<parent link="linkbasemotor"/>
		<child link="link1"/>
		<origin xyz="0.0 -0.02 0.0" rpy="0 0 0" />
		<axis xyz="0 1 0" />
		<limit upper="1.9" lower="-1.9" effort="190" velocity="30" />
	</joint>
	
	<joint name="armjoint2" type="revolute">
		<parent link="link1"/>
		<child link="link2"/>
		<axis xyz="0 1 0" />
		<origin xyz="0.0 0.09 0.28" rpy="0 0 0" />
		<limit upper="1.9" lower="-1.9" effort="190" velocity="30" />
	</joint>
	
	<joint name="armjoint3" type="revolute">
		<parent link="link2"/>
		<child link="link3"/>
		<origin xyz="0.0 0.0 0.13" rpy="0 0 0" />
		<axis xyz="0 0 1" />
		<limit upper="1.7" lower="-1.7" effort="190" velocity="30" />
	</joint>

	<joint name="armjoint4" type="revolute">
		<parent link="link3"/>
		<child link="link4"/>
		<origin xyz="0.0 -0.053 0.065" rpy="0 0 0" />
		<axis xyz="0 0 1" />
		<limit upper="1.7" lower="-1.7" effort="160" velocity="30" />
	</joint>
	
	<joint name="armjoint5" type="revolute">
		<parent link="link4"/>
		<child link="link5"/>
		<origin xyz="0.0 -0.027 0.035" rpy="0 0 0" />
		<axis xyz="0 0 1" />
		<limit upper="1.7" lower="-1.7" effort="160" velocity="30" />
	</joint>
	
	<joint name="handjoint" type="fixed">
		<parent link="link5"/>
		<child link="linkhandbase"/>
	</joint>
  
</robot>
